<?xml version='1.0'?>

<sdf version='1.4'>

<model name="omnidrive">

<static>false</static>

    <link name='chassis'>
        <pose>0 0 0.1 0 0 0</pose>

        <collision name='collision'>
            <geometry>
                <cylinder>
                    <radius>0.2</radius>
                    <length>0.1</length>
                </cylinder>
            </geometry>
        </collision>

        <visual name='visual'>
            <pose>0 0 0.0 0 0 0</pose>
            <geometry>
                <cylinder>
                    <radius>0.2</radius>
                    <length>0.1</length>
                </cylinder>
            </geometry>
        </visual>
    </link>

    <link name="wheel1">
        <pose>0.10875 0.188360525323115 0.1 0 -1.5707963267949 1.0471975511966</pose>

        <collision name="collision">
            <geometry>
                <cylinder>
                    <radius>0.1</radius>
                    <length>0.035</length>
                </cylinder>
            </geometry>

            <surface>
                <friction>
                    <torsional>
                        <coefficient>1.0</coefficient>
                        <ode>
                            <slip>1.0</slip>
                        </ode>
                    </torsional>
                </friction>
            </surface>
        </collision>

        <visual name="visual">
            <geometry>
                <cylinder>
                    <radius>0.1</radius>
                    <length>0.035</length>
                </cylinder>
            </geometry>
        </visual>

        <inertial>
            <mass>0.32</mass>
            <pose>0 0 0 0 0 0</pose>
            <inertia>
                <ixx>0.002602083</ixx>
                <iyy>0.002602083</iyy>
                <izz>0.005</izz>
            </inertia>
        </inertial>
    </link>

    <link name="wheel2">
        <pose>-0.2175 0 0.1 0 -1.5707963267949 0</pose>

        <collision name="collision">
            <geometry>
                <cylinder>
                    <radius>0.1</radius>
                    <length>0.035</length>
                </cylinder>
            </geometry>

            <surface>
                <friction>
                    <torsional>
                        <coefficient>1.0</coefficient>
                        <ode>
                            <slip>1.0</slip>
                        </ode>
                    </torsional>
                </friction>
            </surface>
        </collision>

        <visual name="visual">
            <geometry>
                <cylinder>
                    <radius>0.1</radius>
                    <length>0.035</length>
                </cylinder>
            </geometry>
        </visual>

        <inertial>
            <mass>0.32</mass>
            <pose>0 0 0 0 0 0</pose>
            <inertia>
                <ixx>0.002602083</ixx>
                <iyy>0.002602083</iyy>
                <izz>0.005</izz>
            </inertia>
        </inertial>
    </link>

    <link name="wheel3">
        <pose>0.10875 -0.188360525323115 0.1 0 -1.5707963267949 -1.0471975511966</pose>

        <collision name="collision">
            <geometry>
                <cylinder>
                    <radius>0.1</radius>
                    <length>0.035</length>
                </cylinder>
            </geometry>

            <surface>
                <friction>
                    <torsional>
                        <coefficient>1.0</coefficient>
                        <ode>
                            <slip>1.0</slip>
                        </ode>
                    </torsional>
                </friction>
            </surface>
        </collision>

        <visual name="visual">
            <geometry>
                <cylinder>
                    <radius>0.1</radius>
                    <length>0.035</length>
                </cylinder>
            </geometry>
        </visual>

        <inertial>
            <mass>0.32</mass>
            <pose>0 0 0 0 0 0</pose>
            <inertia>
                <ixx>0.002602083</ixx>
                <iyy>0.002602083</iyy>
                <izz>0.005</izz>
            </inertia>
        </inertial>
    </link>

    <joint type="revolute" name="wheel1_hinge">
        <pose>0 0 -0.0175 0 0 0</pose>
        <child>wheel1</child>
        <parent>chassis</parent>
        <axis>
            <xyz>0.5 0.866025403784439 0</xyz>
        </axis>
    </joint>

    <joint type="revolute" name="wheel2_hinge">
        <pose>0 0 -0.0175 0 0 0</pose>
        <child>wheel2</child>
        <parent>chassis</parent>
        <axis>
            <xyz>-1 0 0</xyz>
        </axis>
    </joint>

    <joint type="revolute" name="wheel3_hinge">
        <pose>0 0 -0.0175 0 0 0</pose>
        <child>wheel3</child>
        <parent>chassis</parent>
        <axis>
            <xyz>0.5 -0.866025403784439 0</xyz>
        </axis>
    </joint>

    <plugin name="object_controller" filename="libgazebo_ros_planar_move.so">
        <commandTopic>cmd_vel</commandTopic>
        <odometryTopic>odom</odometryTopic>
        <odometryFrame>odom</odometryFrame>
        <odometryRate>50.0</odometryRate>
        <robotBaseFrame>chassis</robotBaseFrame>
    </plugin>

    <plugin name="p3d_base_controller" filename="libgazebo_ros_p3d.so">
        <alwaysOn>true</alwaysOn>
        <updateRate>50.0</updateRate>
        <bodyName>chassis</bodyName>
        <topicName>ground_truth/state</topicName>
        <gaussianNoise>0</gaussianNoise>
        <frameName>world</frameName>
        <xyzOffsets>0 0 0</xyzOffsets>
        <rpyOffsets>0 0 0</rpyOffsets>
    </plugin>

</model>

</sdf>
