<?xml version='1.0'?>

<sdf version='1.4'>

<model name="diffdrive">

<static>false</static>

    <link name='chassis'>
        <pose>0 0 0.07 0 0 0</pose>

        <collision name='collision'>
            <geometry>
                <box>
                    <size>.4 .2 .1</size>
                </box>
            </geometry>
        </collision>

        <visual name='visual'>
            <pose>0 0 0 0 0 0</pose>
            <geometry>
                <box>
                    <size>.4 .2 .1</size>
                </box>
            </geometry>
        </visual>

        <collision name='caster_collision'>
            <pose>-0.15 0 -0.05 0 0 0</pose>
            <geometry>
                <sphere>
                    <radius>.0035</radius>
                </sphere>
            </geometry>

            <surface>
                <friction>
                    <ode>
                        <mu>0</mu>
                        <mu2>0</mu2>
                        <slip1>1.0</slip1>
                        <slip2>1.0</slip2>
                    </ode>
                </friction>
            </surface>
        </collision>

        <visual name='caster_visual'>
            <pose>-0.15 0 -0.05 0 0 0</pose>
            <geometry>
                <sphere>
                    <radius>.0035</radius>
                </sphere>
            </geometry>
        </visual>

        <collision name='caster_collision2'>
            <pose>0.15 0 -0.05 0 0 0</pose>
            <geometry>
                <sphere>
                    <radius>.0035</radius>
                </sphere>
            </geometry>

            <surface>
                <friction>
                    <ode>
                        <mu>0</mu>
                        <mu2>0</mu2>
                        <slip1>1.0</slip1>
                        <slip2>1.0</slip2>
                    </ode>
                </friction>
            </surface>
        </collision>

        <visual name='caster_visual2'>
            <pose>0.15 0 -0.05 0 0 0</pose>
            <geometry>
                <sphere>
                    <radius>.0035</radius>
                </sphere>
            </geometry>
        </visual>
    </link>

    <link name="left_wheel">
        <pose>0 0.104 0.07 -1.5707963267949 0 0</pose>

        <collision name="collision">
            <geometry>
                <cylinder>
                    <radius>.07</radius>
                    <length>.008</length>
                </cylinder>
            </geometry>

            <surface>
                <friction>
                    <torsional>
                        <coefficient>1.0</coefficient>
                        <ode>
                            <slip>0</slip>
                        </ode>
                    </torsional>
                </friction>
            </surface>
        </collision>

        <visual name="visual">
            <geometry>
                <cylinder>
                    <radius>.07</radius>
                    <length>.008</length>
                </cylinder>
            </geometry>
        </visual>

        <inertial>
            <mass>.014</mass>
            <pose>0 0 0 0 0 0</pose>
            <inertia>
                <ixx>0.001230333</ixx>
                <iyy>0.001230333</iyy>
                <izz>0.00245</izz>
            </inertia>
        </inertial>
        
    </link>
    
    <link name="right_wheel">
        <pose>0 -0.104 0.07 1.5707963267949 0 0</pose>

        <collision name="collision">
            <geometry>
                <cylinder>
                    <radius>.07</radius>
                    <length>.008</length>
                </cylinder>
            </geometry>

            <surface>
                <friction>
                    <torsional>
                        <coefficient>1.0</coefficient>
                        <ode>
                            <slip>0</slip>
                        </ode>
                    </torsional>
                </friction>
            </surface>
        </collision>

        <visual name="visual">
            <geometry>
                <cylinder>
                    <radius>.07</radius>
                    <length>.008</length>
                </cylinder>
            </geometry>
        </visual>

        <inertial>
            <mass>.014</mass>
            <pose>0 0 0 0 0 0</pose>
            <inertia>
                <ixx>0.001230333</ixx>
                <iyy>0.001230333</iyy>
                <izz>0.00245</izz>
            </inertia>
        </inertial>
        
    </link>

    <joint type="revolute" name="left_wheel_hinge">
        <pose>0 0 -0.004 0 0 0</pose>
        <child>left_wheel</child>
        <parent>chassis</parent>
        <axis>
            <xyz>0 1 0</xyz>
        </axis>
    </joint>

    <joint type="revolute" name="right_wheel_hinge">
        <pose>0 0 -0.004 0 0 0</pose>
        <child>right_wheel</child>
        <parent>chassis</parent>
        <axis>
            <xyz>0 1 0</xyz>
        </axis>
    </joint>

    <plugin name="object_controller" filename="libgazebo_ros_planar_move.so">
        <alwaysOn>true</alwaysOn>
        <commandTopic>cmd_vel</commandTopic>
        <odometryTopic>odom</odometryTopic>
        <odometryFrame>odom</odometryFrame>
        <odometryRate>50.0</odometryRate>
        <robotBaseFrame>chassis</robotBaseFrame>
    </plugin>

    <plugin name="p3d_base_controller" filename="libgazebo_ros_p3d.so">
        <alwaysOn>true</alwaysOn>
        <updateRate>50.0</updateRate>
        <bodyName>chassis</bodyName>
        <topicName>ground_truth/state</topicName>
        <gaussianNoise>0</gaussianNoise>
        <frameName>world</frameName>
        <xyzOffsets>0 0 0</xyzOffsets>
        <rpyOffsets>0 0 0</rpyOffsets>
    </plugin>

</model>

</sdf>