<?xml version='1.0'?>

<sdf version='1.4'>

<model name="diffdrive">

<static>false</static>

    <link name='chassis'>
        <pose>0 0 0.1 0 0 0</pose>

        <inertial>
            <mass>10.0</mass>
            <pose>0.0 0 0.1 0 0 0</pose>
            <inertia>
                <ixx>0.5</ixx>
                <iyy>1.0</iyy>
                <izz>0.1</izz>
            </inertia>
        </inertial>

        <collision name='collision'>
            <geometry>
                <box>
                    <size>.4 .2 .1</size>
                </box>
            </geometry>
        </collision>

        <visual name='visual'>
            <pose>0 0 0.0 0 0 0</pose>
            <geometry>
                <box>
                    <size>.4 .2 .1</size>
                </box>
            </geometry>
        </visual>

        <collision name='caster_collision'>
            <pose>-0.15 0 -0.05 0 0 0</pose>
            <geometry>
                <sphere>
                    <radius>.05</radius>
                </sphere>
            </geometry>

            <surface>
                <friction>
                    <ode>
                        <mu>0</mu>
                        <mu2>0</mu2>
                        <slip1>1.0</slip1>
                        <slip2>1.0</slip2>
                    </ode>
                </friction>
            </surface>
        </collision>

        <visual name='caster_visual'>
            <pose>-0.15 0 -0.05 0 0 0</pose>
            <geometry>
                <sphere>
                    <radius>.05</radius>
                </sphere>
            </geometry>
        </visual>

        <collision name='caster_collision2'>
            <pose>0.15 0 -0.05 0 0 0</pose>
            <geometry>
                <sphere>
                    <radius>.05</radius>
                </sphere>
            </geometry>

            <surface>
                <friction>
                    <ode>
                        <mu>0</mu>
                        <mu2>0</mu2>
                        <slip1>1.0</slip1>
                        <slip2>1.0</slip2>
                    </ode>
                </friction>
            </surface>
        </collision>

        <visual name='caster_visual2'>
            <pose>0.15 0 -0.05 0 0 0</pose>
            <geometry>
                <sphere>
                    <radius>.05</radius>
                </sphere>
            </geometry>
        </visual>
    </link>

    <link name="left_wheel">
        <pose>0 0.125 0.1 -1.5707963267949 0 0</pose>

        <collision name="collision">
            <geometry>
                <cylinder>
                    <radius>.1</radius>
                    <length>.05</length>
                </cylinder>
            </geometry>

            <surface>
                <friction>
                    <ode>
                        <slip1>0</slip1>
                        <slip2>0</slip2>
                    </ode>
                </friction>
            </surface>
        </collision>

        <visual name="visual">
            <geometry>
                <cylinder>
                    <radius>.1</radius>
                    <length>.05</length>
                </cylinder>
            </geometry>
        </visual>
    </link>
    
    <link name="right_wheel">
        <pose>0 -0.125 0.1 1.5707963267949 0 0</pose>

        <collision name="collision">
            <geometry>
                <cylinder>
                    <radius>.1</radius>
                    <length>.05</length>
                </cylinder>
            </geometry>

            <surface>
                <friction>
                    <ode>
                        <slip1>0</slip1>
                        <slip2>0</slip2>
                    </ode>
                </friction>
            </surface>
        </collision>

        <visual name="visual">
            <geometry>
                <cylinder>
                    <radius>.1</radius>
                    <length>.05</length>
                </cylinder>
            </geometry>
        </visual>
    </link>

    <joint type="revolute" name="left_wheel_hinge">
        <pose>0 0 -0.025 0 0 0</pose>
        <child>left_wheel</child>
        <parent>chassis</parent>
        <axis>
            <xyz>0 1 0</xyz>
        </axis>
    </joint>

    <joint type="revolute" name="right_wheel_hinge">
        <pose>0 0 -0.025 0 0 0</pose>
        <child>right_wheel</child>
        <parent>chassis</parent>
        <axis>
            <xyz>0 1 0</xyz>
        </axis>
    </joint>

    <plugin name="object_controller" filename="libgazebo_ros_planar_move.so">
        <commandTopic>cmd_vel</commandTopic>
        <odometryTopic>odom</odometryTopic>
        <odometryFrame>odom</odometryFrame>
        <odometryRate>20.0</odometryRate>
        <robotBaseFrame>chassis</robotBaseFrame>
    </plugin>

</model>

</sdf>